Workbook
Name Text17: 'Std-Erf'!#REF!
Name Text18: 'Std-Erf'!#REF!
Name Text19: 'Std-Erf'!#REF!
Name Text20: 'Std-Erf'!#REF!

Sheet Std-Erf
A1: Monat | B1: März 2026 | C1: 2026 | D1: Auszahlung per | F1: 46122
A2: Name | B2: . | C2: Spesen Nachweis | D2: STUNDEN | E2: ZUSCHLÄGE NSF | F2: Betrag
A3: Blesinger | B3: Reto | F3: =BleR!G42 -> 0
A4: Blesinger | B4: Diana | F4: =BleD!G43 -> 0
A5: Baumann | B5: Rolf | F5: =BauR!G42 -> 0
A6: Beirer | B6: Clemens | F6: =BeiC!G44 -> 0
A7: Birrer | B7: Bruno | F7: =BirB!G42 -> 0
A8: Birrer | B8: Rinaldo | F8: =BirR!G42 -> 0
A9: Camozzi | B9: Fabio | F9: =CamF!G42 -> 0
A10: Camozzi | B10: Fabio Seminar | F10: ='CamF Seminar'!G42 -> 0
A11: Coray | B11: Bryan | F11: =CorB!G42 -> 0
A12: Costa | B12: Fabio | F12: =CosF!G42 -> 0
A13: Diz | B13: Humberto | F13: =DizH!G42 -> 0
A14: Duchene | B14: Renato | F14: =DuR!G43 -> 0
A15: Egli | B15: Andrea | F15: =EgliA!G43 -> 0
A16: Egli | B16: Bettina | F16: =EgliB!G42 -> 0
A17: Gabriel | B17: Abraham | F17: =GabA!G43 -> -410.45
A18: Gabriel | B18: Patrick | F18: =GabP!G42 -> 0
A19: Grüter | B19: Benedikt | F19: =GrBe!G42 -> 0
A20: Hiestand | B20: Philipp | F20: =HieP!G42 -> 0
A21: Hug | B21: Shirin | F21: =HugS!G43 -> 0
A22: Käch | B22: Jannine | F22: =KäJ!G43 -> 0
A23: Käch | B23: Yvonne | F23: =KäY!G43 -> 0
A24: Kolb | B24: Mike | F24: =KolM!G42 -> 0
A25: Kolb, Spesen | B25: Mike | C25: =KolMSpesen!G40 -> 50 | D25: 3.25 | F25: =KolMSpesen!G42 -> 150.05
A26: Kostovic | B26: Ivan | F26: =KosI!G42 -> 0
A27: Lindenmeyer | B27: Sebastian | F27: =LinS!G42 -> 0
A28: Lussi | B28: Werner | F28: =LusWJ!G42 -> 0
A29: Lussi | B29: Werner Sen | F29: =LusWS!G42 -> 0
A30: Pegoraro | B30: Jan | F30: =PegJ!G42 -> 0
A31: Prenqaj | B31: Gjesika | F31: =PreG!G44 -> -13
A32: Prenqaj | B32: Zef | F32: =PreZ!G44 -> 0
A33: Roccasalva | B33: Julijana | F33: =RocJ!G42 -> 0
A34: Roccasalva | B34: Raffaele | F34: =RocR!G42 -> 0
A35: Schaffner | B35: Andreas | F35: =SchA!G42 -> 0
A36: Stalder | B36: Severin | F36: =StaS!G43 -> 0
A37: Stocker | B37: Norina | F37: =StoN!G43 -> -125.25
A38: Total Löhne | F38: =SUM(F3:F37) -> -398.65

Sheet BleR
A1: Blesinger Sicherheits Dienste GmbH
A2: Postfach 28
A3: 6314 Unterägeri
A4: www.blesingersicherheit.ch
A5: info@blesingersicherheit.ch
D7: Herr
D8: Reto Blesinger
D9: Weinbergstrasse 8
D10: 6340 Baar
A12: AHV Nr. 756.1143.0759.88
A14: Lohnblatt | B14: ='Std-Erf'!B1 -> März 2026
A16: Abteilung | B16: Sicherheit | D16: Anstellungskategorie | F16: C
A18: Abrechnungsdatum | B18: ='Std-Erf'!F1 -> 46122 | D18: Anstellungsort | F18: Weinbergstrasse 8, Baar
A19: Gesamtstunden gemäss beigelgtem Stundennachweis | D19: Dienstjahr | F19: 22
A21: Bezeichnung | E21: Einheit | F21: Ansatz | G21: Betrag
A23: Basislohn | D23: Std. | E23: ='Std-Erf'!D3 -> 0 | F23: 27 | G23: =PRODUCT(E23:F23) -> 0
A24: Stunden mit Zeitzuschlag | C24: ='Std-Erf'!E3 -> 0 | D24: Std. | E24: =C24/10 -> 0 | F24: 27 | G24: =PRODUCT(E24:F24) -> 0
A25: Spezialzuschlag gemäss Vertrag | D25: Std. | E25: =E23 -> 0 | F25: 3 | G25: =PRODUCT(E25:F25) -> 0
A26: Fahrzeitentschädigung | C26: Pauschalzone | D26: 1 | E26: 0 | F26: 5.6 | G26: =PRODUCT(E26:F26) -> 0
A27: Fahrzeitentschädigung | C27: Pauschalzone | D27: 2 | E27: 0 | F27: 16.8 | G27: =PRODUCT(E27:F27) -> 0
A28: Fahrzeitentschädigung | C28: Regiezone | E28: 0 | F28: 0.32 | G28: =PRODUCT(E28:F28) -> 0
A29: Zwischentotal | G29: =SUM(G23:G28) -> 0
A31: Ferienentschädigung | F31: 0.1064 | G31: =PRODUCT(G29*F31) -> 0
A32: AHV pflichtiger Bruttolohn | G32: =SUM(G29+G31) -> 0
A34: AHV/IV/EO | F34: 0.053 | G34: =PRODUCT(G32*F34) -> 0
A35: ALV | F35: 0.011 | G35: =PRODUCT(G32*F35) -> 0
A36: Krankentaggeld/UVG | F36: 0.00821 | G36: =PRODUCT(G32*F36) -> 0
A37: Aus- und Weiterbildungskosten inkl. Ferienentschädigung | E37: =(E23+E24)*1.0833 -> 0 | F37: 0.015 | G37: =PRODUCT(E37,F37) -> 0
A38: Total | G38: =SUM(G32-(G34+G35+G36+G37)) -> 0
A40: Spesen gemäss Nachweis | G40: ='Std-Erf'!C3 -> 0
A42: Total Auszahlung | G42: =ROUND(SUM(G38:G40)*20,0)/20 -> 0
A45: Ferienguthaben | B45: 0 | D45: Krankheitstage bezahlt | F45: 0
A46: Abwesenheit | B46: 0 | D46: Mehrzeit/Unterzeit | F46: 0
A48: Wir bitten Sie die Lohnabrechnung sofort zu prüfen und Unstimmigkeiten schriftlich innerhalb von 10 Tagen
A49: per Mail mitzuteilen!
C51: Freundliche Grüsse
C53: Blesinger Sicherheitsdienste GmbH

Sheet BleD
A1: Blesinger Sicherheits Dienste GmbH
A2: Postfach 28
A3: 6314 Unterägeri
A4: www.blesingersicherheit.ch
A5: info@blesingersicherheit.ch
D7: Frau
D8: Diana Blesinger
D9: Waldheimstrasse 43
D10: 6314 Unterägeri
A12: AHV Nr. 756.6420 3981 49
A14: Lohnblatt | B14: ='Std-Erf'!B1 -> März 2026
A16: Abteilung | B16: Administration | D16: Anstellungskategorie | F16: Nicht GAV Pflichtig
A18: Abrechnungsdatum | B18: ='Std-Erf'!F1 -> 46122 | D18: Anstellungsort | F18: Rainstrasse 37, Unterägeri
A19: Gesamtstunden gemäss beigelgtem Stundennachweis | D19: Dienstjahr | F19: 0
A21: Bezeichnung | E21: Einheit | F21: Ansatz | G21: Betrag
A23: Basislohn | D23: Std. | E23: ='Std-Erf'!D4 -> 0 | F23: 50 | G23: =PRODUCT(E23:F23) -> 0
A24: Stunden mit Zeitzuschlag | E24: =C24/10 -> 0 | F24: 0 | G24: =PRODUCT(E24:F24) -> 0
A25: Spezialzuschlag gemäss Vertrag | E25: 0 | F25: 0 | G25: =PRODUCT(E25:F25) -> 0
A26: Fahrzeitentschädigung | C26: Pauschalzone | D26: 1 | E26: 0 | F26: 5.6 | G26: =PRODUCT(E26:F26) -> 0
A27: Fahrzeitentschädigung | C27: Pauschalzone | D27: 2 | E27: 0 | F27: 16.8 | G27: =PRODUCT(E27:F27) -> 0
A28: Fahrzeitentschädigung | C28: Regiezone | E28: 0 | F28: 0.32 | G28: =PRODUCT(E28:F28) -> 0
A29: Zwischentotal | G29: =SUM(G23:G28) -> 0
A31: Ferienentschädigung | F31: 0 | G31: =PRODUCT(G29*F31) -> 0
A32: AHV pflichtiger Bruttolohn | G32: =SUM(G29+G31) -> 0
A34: AHV/IV/EO | F34: 0.053 | G34: =PRODUCT(G32*F34) -> 0
A35: ALV | F35: 0.011 | G35: =PRODUCT(G32*F35) -> 0
A36: Krankentaggeld/UVG | F36: 0.00821 | G36: =PRODUCT(G32*F36) -> 0
A37: BVG Arbeitnehmeranteil
A38: Aus- und Weiterbildungskosten inkl. Ferienentschädigung | G38: =PRODUCT(E38,F38) -> 0
A39: Total | G39: =SUM(G32-(G34+G35+G36+G38+G37)) -> 0
A41: Spesen gemäss Nachweis | G41: ='Std-Erf'!C4 -> 0
A43: Total Auszahlung | G43: =ROUND(SUM(G39:G41)*20,0)/20 -> 0
A46: Ferienguthaben | B46: 0 | D46: Krankheitstage bezahlt | F46: 0
A47: Abwesenheit | B47: 0 | D47: Mehrzeit/Unterzeit | F47: 0
A49: Wir bitten Sie die Lohnabrechnung sofort zu prüfen und Unstimmigkeiten schriftlich innerhalb von 10 Tagen
A50: per Mail mitzuteilen!
C52: Freundliche Grüsse
C54: Blesinger Sicherheitsdienste GmbH

Sheet BauR
A1: Blesinger Sicherheits Dienste GmbH
A2: Postfach 28
A3: 6314 Unterägeri
A4: www.blesingersicherheit.ch
A5: info@blesingersicherheit.ch
D7: Herr
D8: Rolf Markus Baumann
D9: Stutzrain 57
D10: 6005 St. Niklausen
A12: AHV Nr. 756.3562.5832.97
A14: Lohnblatt | B14: ='Std-Erf'!B1 -> März 2026
A16: Abteilung | B16: Sicherheit | D16: Anstellungskategorie | F16: C
A18: Abrechnungsdatum | B18: ='Std-Erf'!F1 -> 46122 | D18: Anstellungsort | F18: Schachenstr. 7, Emmenbrücke
A19: Gesamtstunden gemäss beigelgtem Stundennachweis | D19: Dienstjahr | F19: 1
A21: Bezeichnung | E21: Einheit | F21: Ansatz | G21: Betrag
A23: Basislohn | D23: Std. | E23: ='Std-Erf'!D5 -> 0 | F23: 25.2 | G23: =PRODUCT(E23:F23) -> 0
A24: Stunden mit Zeitzuschlag | C24: ='Std-Erf'!E5 -> 0 | D24: Std. | E24: =C24/10 -> 0 | F24: 25.2 | G24: =PRODUCT(E24:F24) -> 0
A25: Spezialzuschlag gemäss Vertrag | G25: =PRODUCT(E25:F25) -> 0
A26: Fahrzeitentschädigung | C26: Pauschalzone | D26: 1 | E26: 0 | F26: 5.6 | G26: =PRODUCT(E26:F26) -> 0
A27: Fahrzeitentschädigung | C27: Pauschalzone | D27: 2 | E27: 0 | F27: 16.8 | G27: =PRODUCT(E27:F27) -> 0
A28: Fahrzeitentschädigung | C28: Regiezone | E28: 0 | F28: 0.32 | G28: =PRODUCT(E28:F28) -> 0
A29: Zwischentotal | G29: =SUM(G23:G28) -> 0
A31: Ferienentschädigung | F31: 0.1064 | G31: =PRODUCT(G29*F31) -> 0
A32: AHV pflichtiger Bruttolohn | G32: =SUM(G29+G31) -> 0
A34: AHV/IV/EO | F34: 0.053 | G34: =PRODUCT(G32*F34) -> 0
A35: ALV | F35: 0.011 | G35: =PRODUCT(G32*F35) -> 0
A36: Krankentaggeld/UVG | F36: 0.00821 | G36: =PRODUCT(G32*F36) -> 0
A37: Aus- und Weiterbildungskosten inkl. Ferienentschädigung | E37: =(E23+E24)*1.0833 -> 0 | F37: 0.015 | G37: =PRODUCT(E37,F37) -> 0
A38: Total | G38: =SUM(G32-(G34+G35+G36+G37)) -> 0
A40: Spesen gemäss Nachweis | G40: ='Std-Erf'!C5 -> 0
A42: Total Auszahlung | G42: =ROUND(SUM(G38:G40)*20,0)/20 -> 0
A45: Ferienguthaben | B45: 0 | D45: Krankheitstage bezahlt | F45: 0
A46: Abwesenheit | B46: 0 | D46: Mehrzeit/Unterzeit | F46: 0
A48: Wir bitten Sie die Lohnabrechnung sofort zu prüfen und Unstimmigkeiten schriftlich innerhalb von 10 Tagen
A49: per Mail mitzuteilen!
C51: Freundliche Grüsse
C53: Blesinger Sicherheitsdienste GmbH

Sheet BeiC
A1: Blesinger Sicherheits Dienste GmbH
A2: Postfach 28
A3: 6314 Unterägeri
A4: www.blesingersicherheit.ch
A5: info@blesingersicherheit.ch
D7: Herr
D8: Beirer Clemens
D9: Im Adelmann 7
D10: 6422 Steinen
A12: AHV Nr. 756.1977.5052.62
A14: Lohnblatt | B14: ='Std-Erf'!B1 -> März 2026
A16: Abteilung | B16: Sicherheit | D16: Anstellungskategorie | F16: C
A18: Abrechnungsdatum | B18: ='Std-Erf'!F1 -> 46122 | D18: Anstellungsort | F18: Weinbergstrasse 8, Baar
A19: Gesamtstunden gemäss beigelgtem Stundennachweis | D19: Dienstjahr | F19: 2
A21: Bezeichnung | E21: Einheit | F21: Ansatz | G21: Betrag
A23: Basislohn | D23: Std. | E23: ='Std-Erf'!D6 -> 0 | F23: 25.2 | G23: =PRODUCT(E23:F23) -> 0
A24: Stunden mit Zeitzuschlag | C24: ='Std-Erf'!E6 -> 0 | D24: Std. | E24: =C24/10 -> 0 | F24: 25.2 | G24: =PRODUCT(E24:F24) -> 0
A25: Spezialzuschlag gemäss Vertrag | G25: =PRODUCT(E25:F25) -> 0
A26: Fahrzeitentschädigung | C26: Pauschalzone | D26: 1 | E26: 0 | F26: 5.6 | G26: =PRODUCT(E26:F26) -> 0
A27: Fahrzeitentschädigung | C27: Pauschalzone | D27: 2 | E27: 0 | F27: 16.8 | G27: =PRODUCT(E27:F27) -> 0
A28: Fahrzeitentschädigung | C28: Regiezone | E28: 0 | F28: 0.32 | G28: =PRODUCT(E28:F28) -> 0
A29: Zwischentotal | G29: =SUM(G23:G28) -> 0
A31: Ferienentschädigung | F31: 0.0833 | G31: =PRODUCT(G29*F31) -> 0
A32: AHV pflichtiger Bruttolohn | G32: =SUM(G29+G31) -> 0
A34: AHV/IV/EO | F34: 0.053 | G34: =PRODUCT(G32*F34) -> 0
A35: ALV | F35: 0.011 | G35: =PRODUCT(G32*F35) -> 0
A36: Krankentaggeld/UVG | F36: 0.00821 | G36: =PRODUCT(G32*F36) -> 0
A37: Quellensteuer Tarif COY vom AHV pflichtigen Bruttolohn | F37: 0.0351 | G37: =G32*F37 -> 0
A38: Quellensteuer Korrektur | G38: 0
A39: Aus- und Weiterbildungskosten inkl. Ferienentschädigung | E39: =(E23+E24)*1.0833 -> 0 | F39: 0.015 | G39: =PRODUCT(E39,F39) -> 0
A40: Total | G40: =SUM(G32-(G34+G35+G36+G37+G39+G38)) -> 0
A42: Spesen gemäss Nachweis | G42: ='Std-Erf'!C6 -> 0
A44: Total Auszahlung | G44: =ROUND(SUM(G40:G42)*20,0)/20 -> 0
A47: Ferienguthaben | B47: 0 | D47: Krankheitstage bezahlt | F47: 0
A48: Abwesenheit | B48: 0 | D48: Mehrzeit/Unterzeit | F48: 0
A50: Wir bitten Sie die Lohnabrechnung sofort zu prüfen und Unstimmigkeiten schriftlich innerhalb von 10 Tagen
A51: per Mail mitzuteilen!
C53: Freundliche Grüsse
C55: Blesinger Sicherheitsdienste GmbH

Sheet BirB
A1: Blesinger Sicherheits Dienste GmbH
A2: Postfach 28
A3: 6314 Unterägeri
A4: www.blesingersicherheit.ch
A5: info@blesingersicherheit.ch
D7: Herr
D8: Bruno Birrer
D9: Obernauerstrasse 90
D10: 6012 Obernau
A12: AHV Nr. 756.5410.8021.92
A14: Lohnblatt | B14: ='Std-Erf'!B1 -> März 2026
A16: Abteilung | B16: Sicherheit | D16: Anstellungskategorie | F16: C
A18: Abrechnungsdatum | B18: ='Std-Erf'!F1 -> 46122 | D18: Anstellungsort | F18: Schachenstr. 7, Emmenbrücke
A19: Gesamtstunden gemäss beigelgtem Stundennachweis | D19: Dienstjahr | F19: 3
A21: Bezeichnung | E21: Einheit | F21: Ansatz | G21: Betrag
A23: Basislohn | D23: Std. | E23: ='Std-Erf'!D7 -> 0 | F23: 25.2 | G23: =PRODUCT(E23:F23) -> 0
A24: Stunden mit Zeitzuschlag | C24: ='Std-Erf'!E7 -> 0 | D24: Std. | E24: =C24/10 -> 0 | F24: 25.2 | G24: =PRODUCT(E24:F24) -> 0
A25: Spezialzuschlag gemäss Vertrag | E25: =E23 -> 0 | F25: 2 | G25: =PRODUCT(E25:F25) -> 0
A26: Fahrzeitentschädigung | C26: Pauschalzone | D26: 1 | E26: 0 | F26: 5.6 | G26: =PRODUCT(E26:F26) -> 0
A27: Fahrzeitentschädigung | C27: Pauschalzone | D27: 2 | E27: 0 | F27: 16.8 | G27: =PRODUCT(E27:F27) -> 0
A28: Fahrzeitentschädigung | C28: Regiezone | E28: 0 | F28: 0.32 | G28: =PRODUCT(E28:F28) -> 0
A29: Zwischentotal | G29: =SUM(G23:G28) -> 0
A31: Ferienentschädigung | F31: 0.1064 | G31: =PRODUCT(G29*F31) -> 0
A32: AHV pflichtiger Bruttolohn | G32: =SUM(G29+G31) -> 0
A34: AHV/IV/EO | F34: 0.053 | G34: =PRODUCT(G32*F34) -> 0
A35: ALV | F35: 0.011 | G35: =PRODUCT(G32*F35) -> 0
A36: Krankentaggeld/UVG | F36: 0.00821 | G36: =PRODUCT(G32*F36) -> 0
A37: Aus- und Weiterbildungskosten inkl. Ferienentschädigung | E37: =(E23+E24)*1.0833 -> 0 | F37: 0.015 | G37: =PRODUCT(E37,F37) -> 0
A38: Total | G38: =SUM(G32-(G34+G35+G36+G37)) -> 0
A40: Spesen gemäss Nachweis | G40: ='Std-Erf'!C7 -> 0
A42: Total Auszahlung | G42: =ROUND(SUM(G38:G40)*20,0)/20 -> 0
A45: Ferienguthaben | B45: 0 | D45: Krankheitstage bezahlt | F45: 0
A46: Abwesenheit | B46: 0 | D46: Mehrzeit/Unterzeit | F46: 0
A48: Wir bitten Sie die Lohnabrechnung sofort zu prüfen und Unstimmigkeiten schriftlich innerhalb von 10 Tagen
A49: per Mail mitzuteilen!
C51: Freundliche Grüsse
C53: Blesinger Sicherheitsdienste GmbH

Sheet BirR
A1: Blesinger Sicherheits Dienste GmbH
A2: Postfach 28
A3: 6314 Unterägeri
A4: www.blesingersicherheit.ch
A5: info@blesingersicherheit.ch
D7: Herr
D8: Rinaldo Birrer
D9: Obernauerstrasse 90
D10: 6012 Obernau
A12: AHV Nr. 756.2028.9360.80
A14: Lohnblatt | B14: ='Std-Erf'!B1 -> März 2026
A16: Abteilung | B16: Sicherheit | D16: Anstellungskategorie | F16: C
A18: Abrechnungsdatum | B18: ='Std-Erf'!F1 -> 46122 | D18: Anstellungsort | F18: Schachenstr. 7, Emmenbrücke
A19: Gesamtstunden gemäss beigelgtem Stundennachweis | D19: Dienstjahr | F19: 3
A21: Bezeichnung | E21: Einheit | F21: Ansatz | G21: Betrag
A23: Basislohn | D23: Std. | E23: ='Std-Erf'!D8 -> 0 | F23: 25.2 | G23: =PRODUCT(E23:F23) -> 0
A24: Stunden mit Zeitzuschlag | C24: ='Std-Erf'!E8 -> 0 | D24: Std. | E24: =C24/10 -> 0 | F24: 25.2 | G24: =PRODUCT(E24:F24) -> 0
A25: Spezialzuschlag gemäss Vertrag | G25: =PRODUCT(E25:F25) -> 0
A26: Fahrzeitentschädigung | C26: Pauschalzone | D26: 1 | E26: 0 | F26: 5.6 | G26: =PRODUCT(E26:F26) -> 0
A27: Fahrzeitentschädigung | C27: Pauschalzone | D27: 2 | E27: 0 | F27: 16.8 | G27: =PRODUCT(E27:F27) -> 0
A28: Fahrzeitentschädigung | C28: Regiezone | E28: 0 | F28: 0.32 | G28: =PRODUCT(E28:F28) -> 0
A29: Zwischentotal | G29: =SUM(G23:G28) -> 0
A31: Ferienentschädigung | F31: 0.0833 | G31: =PRODUCT(G29*F31) -> 0
A32: AHV pflichtiger Bruttolohn | G32: =SUM(G29+G31) -> 0
A34: AHV/IV/EO | F34: 0.053 | G34: =PRODUCT(G32*F34) -> 0
A35: ALV | F35: 0.011 | G35: =PRODUCT(G32*F35) -> 0
A36: Krankentaggeld/UVG | F36: 0.00821 | G36: =PRODUCT(G32*F36) -> 0
A37: Aus- und Weiterbildungskosten inkl. Ferienentschädigung | E37: =(E23+E24)*1.0833 -> 0 | F37: 0.015 | G37: =PRODUCT(E37,F37) -> 0
A38: Total | G38: =SUM(G32-(G34+G35+G36+G37)) -> 0
A40: Spesen gemäss Nachweis | G40: ='Std-Erf'!C8 -> 0
A42: Total Auszahlung | G42: =ROUND(SUM(G38:G40)*20,0)/20 -> 0
A45: Ferienguthaben | B45: 0 | D45: Krankheitstage bezahlt | F45: 0
A46: Abwesenheit | B46: 0 | D46: Mehrzeit/Unterzeit | F46: 0
A48: Wir bitten Sie die Lohnabrechnung sofort zu prüfen und Unstimmigkeiten schriftlich innerhalb von 10 Tagen
A49: per Mail mitzuteilen!
C51: Freundliche Grüsse
C53: Blesinger Sicherheitsdienste GmbH

Sheet CamF
A1: Blesinger Sicherheits Dienste GmbH
A2: Postfach 28
A3: 6314 Unterägeri
A4: www.blesingersicherheit.ch
A5: info@blesingersicherheit.ch
D7: Herr
D8: Fabio Camozzi
D9: Höhenstrasse 13
D10: 6313 Edlibach
A12: AHV Nr. 756.3741.3891.15
A14: Lohnblatt | B14: ='Std-Erf'!B1 -> März 2026
A16: Abteilung | B16: Sicherheit | D16: Anstellungskategorie | F16: C
A18: Abrechnungsdatum | B18: ='Std-Erf'!F1 -> 46122 | D18: Anstellungsort | F18: Weinbergstrasse 8, Baar
A19: Gesamtstunden gemäss beigelgtem Stundennachweis | D19: Dienstjahr | F19: 10
A21: Bezeichnung | E21: Einheit | F21: Ansatz | G21: Betrag
A23: Basislohn | D23: Std. | E23: ='Std-Erf'!D9 -> 0 | F23: 27 | G23: =PRODUCT(E23:F23) -> 0
A24: Stunden mit Zeitzuschlag | C24: ='Std-Erf'!E9 -> 0 | D24: Std. | E24: =C24/10 -> 0 | F24: 27 | G24: =PRODUCT(E24:F24) -> 0
A25: Spezialzuschlag gemäss Vertrag | D25: Std. | E25: =E23 -> 0 | F25: 3 | G25: =PRODUCT(E25:F25) -> 0
A26: Fahrzeitentschädigung | C26: Pauschalzone | D26: 1 | E26: 0 | F26: 5.6 | G26: =PRODUCT(E26:F26) -> 0
A27: Fahrzeitentschädigung | C27: Pauschalzone | D27: 2 | E27: 0 | F27: 16.8 | G27: =PRODUCT(E27:F27) -> 0
A28: Fahrzeitentschädigung | C28: Regiezone | E28: 0 | F28: 0.32 | G28: =PRODUCT(E28:F28) -> 0
A29: Zwischentotal | G29: =SUM(G23:G28) -> 0
A31: Ferienentschädigung | F31: 0.0833 | G31: =PRODUCT(G29*F31) -> 0
A32: AHV pflichtiger Bruttolohn | G32: =SUM(G29+G31) -> 0
A34: AHV/IV/EO | F34: 0.053 | G34: =PRODUCT(G32*F34) -> 0
A35: ALV | F35: 0.011 | G35: =PRODUCT(G32*F35) -> 0
A36: Krankentaggeld/UVG | F36: 0.00821 | G36: =PRODUCT(G32*F36) -> 0
A37: Aus- und Weiterbildungskosten inkl. Ferienentschädigung | E37: =(E23+E24)*1.0833 -> 0 | F37: 0.015 | G37: =PRODUCT(E37,F37) -> 0
A38: Total | G38: =SUM(G32-(G34+G35+G36+G37)) -> 0
A40: Spesen gemäss Nachweis | G40: ='Std-Erf'!C9 -> 0
A42: Total Auszahlung | G42: =ROUND(SUM(G38:G40)*20,0)/20 -> 0
A45: Ferienguthaben | B45: 0 | D45: Krankheitstage bezahlt | F45: 0
A46: Abwesenheit | B46: 0 | D46: Mehrzeit/Unterzeit | F46: 0
A48: Wir bitten Sie die Lohnabrechnung sofort zu prüfen und Unstimmigkeiten schriftlich innerhalb von 10 Tagen
A49: per Mail mitzuteilen!
C51: Freundliche Grüsse
C53: Blesinger Sicherheitsdienste GmbH

Sheet CamF Seminar
A1: Blesinger Sicherheits Dienste GmbH
A2: Postfach 28
A3: 6314 Unterägeri
A4: www.blesingersicherheit.ch
A5: info@blesingersicherheit.ch
D7: Herr
D8: Fabio Camozzi
D9: Höhenstrasse 13
D10: 6313 Edlibach
A12: AHV Nr. 756.3741.3891.15
A14: Lohnblatt | B14: ='Std-Erf'!B1 -> März 2026
A16: Abteilung | B16: Seminar | D16: Anstellungskategorie | F16: C
A18: Abrechnungsdatum | B18: ='Std-Erf'!F1 -> 46122 | D18: Anstellungsort | F18: Weinbergstrasse 8, Baar
A19: Gesamtstunden gemäss beigelgtem Stundennachweis | D19: Dienstjahr | F19: 9
A21: Bezeichnung | E21: Einheit | F21: Ansatz | G21: Betrag
A23: Basislohn | D23: Std. | E23: ='Std-Erf'!D10 -> 0 | F23: 62.5 | G23: =PRODUCT(E23:F23) -> 0
A24: Stunden mit Zeitzuschlag | D24: Std. | E24: =C24/10 -> 0 | F24: 25.2 | G24: =PRODUCT(E24:F24) -> 0
A25: Spezialzuschlag gemäss Vertrag | D25: Std. | E25: 0 | F25: 3 | G25: =PRODUCT(E25:F25) -> 0
A26: Fahrzeitentschädigung | C26: Pauschalzone | D26: 1 | E26: 0 | F26: 5.6 | G26: =PRODUCT(E26:F26) -> 0
A27: Fahrzeitentschädigung | C27: Pauschalzone | D27: 2 | E27: 0 | F27: 16.8 | G27: =PRODUCT(E27:F27) -> 0
A28: Fahrzeitentschädigung | C28: Regiezone | E28: 0 | F28: 0.32 | G28: =PRODUCT(E28:F28) -> 0
A29: Zwischentotal | G29: =SUM(G23:G28) -> 0
A31: Ferienentschädigung | F31: 0 | G31: =PRODUCT(G29*F31) -> 0
A32: AHV pflichtiger Bruttolohn | G32: =SUM(G29+G31) -> 0
A34: AHV/IV/EO | F34: 0.053 | G34: =PRODUCT(G32*F34) -> 0
A35: ALV | F35: 0.011 | G35: =PRODUCT(G32*F35) -> 0
A36: Krankentaggeld/UVG | F36: 0.00821 | G36: =PRODUCT(G32*F36) -> 0
A37: Aus- und Weiterbildungskosten inkl. Ferienentschädigung | E37: =(E23+E24)*1.0833 -> 0 | F37: 0.015 | G37: =PRODUCT(E37,F37) -> 0
A38: Total | G38: =SUM(G32-(G34+G35+G36+G37)) -> 0
A40: Spesen gemäss Nachweis | G40: ='Std-Erf'!C10 -> 0
A42: Total Auszahlung | G42: =ROUND(SUM(G38:G40)*20,0)/20 -> 0
A45: Ferienguthaben | B45: 0 | D45: Krankheitstage bezahlt | F45: 0
A46: Abwesenheit | B46: 0 | D46: Mehrzeit/Unterzeit | F46: 0
A48: Wir bitten Sie die Lohnabrechnung sofort zu prüfen und Unstimmigkeiten schriftlich innerhalb von 10 Tagen
A49: per Mail mitzuteilen!
C51: Freundliche Grüsse
C53: Blesinger Sicherheitsdienste GmbH

Sheet CorB
A1: Blesinger Sicherheits Dienste GmbH
A2: Postfach 28
A3: 6314 Unterägeri
A4: www.blesingersicherheit.ch
A5: info@blesingersicherheit.ch
D7: Herr
D8: Bryan Coray
D9: Langackerstrasse 2
D10: 6330 Cham
A12: AHV Nr. 756.4542.3093.26
A14: Lohnblatt | B14: ='Std-Erf'!B1 -> März 2026
A16: Abteilung | B16: Sicherheit | D16: Anstellungskategorie | F16: C
A18: Abrechnungsdatum | B18: ='Std-Erf'!F1 -> 46122 | D18: Anstellungsort | F18: Weinbergstrasse 8, Baar
A19: Gesamtstunden gemäss beigelgtem Stundennachweis | D19: Dienstjahr | F19: 2
A21: Bezeichnung | E21: Einheit | F21: Ansatz | G21: Betrag
A23: Basislohn | D23: Std. | E23: ='Std-Erf'!D11 -> 0 | F23: 27.2 | G23: =PRODUCT(E23:F23) -> 0
A24: Stunden mit Zeitzuschlag | C24: ='Std-Erf'!E11 -> 0 | D24: Std. | E24: =C24/10 -> 0 | F24: 27.2 | G24: =PRODUCT(E24:F24) -> 0
A25: Spezialzuschlag gemäss Vertrag | G25: =PRODUCT(E25:F25) -> 0
A26: Fahrzeitentschädigung | C26: Pauschalzone | D26: 1 | E26: 0 | F26: 5.6 | G26: =PRODUCT(E26:F26) -> 0
A27: Fahrzeitentschädigung | C27: Pauschalzone | D27: 2 | E27: 0 | F27: 16.8 | G27: =PRODUCT(E27:F27) -> 0
A28: Fahrzeitentschädigung | C28: Regiezone | E28: 0 | F28: 0.32 | G28: =PRODUCT(E28:F28) -> 0
A29: Zwischentotal | G29: =SUM(G23:G28) -> 0
A31: Ferienentschädigung | F31: 0.0833 | G31: =PRODUCT(G29*F31) -> 0
A32: AHV pflichtiger Bruttolohn | G32: =SUM(G29+G31) -> 0
A34: AHV/IV/EO | F34: 0.053 | G34: =PRODUCT(G32*F34) -> 0
A35: ALV | F35: 0.011 | G35: =PRODUCT(G32*F35) -> 0
A36: Krankentaggeld/UVG | F36: 0.00821 | G36: =PRODUCT(G32*F36) -> 0
A37: Aus- und Weiterbildungskosten inkl. Ferienentschädigung | E37: =(E23+E24)*1.0833 -> 0 | F37: 0.015 | G37: =PRODUCT(E37,F37) -> 0
A38: Total | G38: =SUM(G32-(G34+G35+G36+G37)) -> 0
A40: Spesen gemäss Nachweis | G40: ='Std-Erf'!C11 -> 0
A42: Total Auszahlung | G42: =ROUND(SUM(G38:G40)*20,0)/20 -> 0
A45: Ferienguthaben | B45: 0 | D45: Krankheitstage bezahlt | F45: 0
A46: Abwesenheit | B46: 0 | D46: Mehrzeit/Unterzeit | F46: 0
A48: Wir bitten Sie die Lohnabrechnung sofort zu prüfen und Unstimmigkeiten schriftlich innerhalb von 10 Tagen
A49: per Mail mitzuteilen!
C51: Freundliche Grüsse
C53: Blesinger Sicherheitsdienste GmbH

Sheet CosF
A1: Blesinger Sicherheits Dienste GmbH
A2: Postfach 28
A3: 6314 Unterägeri
A4: www.blesingersicherheit.ch
A5: info@blesingersicherheit.ch
D7: Herr
D8: Fabio Costa
D9: Bachmattli 2
D10: 6314 Unterägeri
A12: AHV Nr. 756.2995.3306.07
A14: Lohnblatt | B14: ='Std-Erf'!B1 -> März 2026
A16: Abteilung | B16: Sicherheit | D16: Anstellungskategorie | F16: C
A18: Abrechnungsdatum | B18: ='Std-Erf'!F1 -> 46122 | D18: Anstellungsort | F18: Weinbergstrasse 8, Baar
A19: Gesamtstunden gemäss beigelgtem Stundennachweis | D19: Dienstjahr | F19: 3
A21: Bezeichnung | E21: Einheit | F21: Ansatz | G21: Betrag
A23: Basislohn | D23: Std. | E23: ='Std-Erf'!D12 -> 0 | F23: 27.2 | G23: =PRODUCT(E23:F23) -> 0
A24: Stunden mit Zeitzuschlag | C24: ='Std-Erf'!E12 -> 0 | D24: Std. | E24: =C24/10 -> 0 | F24: 27.2 | G24: =PRODUCT(E24:F24) -> 0
A25: Spezialzuschlag gemäss Vertrag | G25: =PRODUCT(E25:F25) -> 0
A26: Fahrzeitentschädigung | C26: Pauschalzone | D26: 1 | E26: 0 | F26: 5.6 | G26: =PRODUCT(E26:F26) -> 0
A27: Fahrzeitentschädigung | C27: Pauschalzone | D27: 2 | E27: 0 | F27: 16.8 | G27: =PRODUCT(E27:F27) -> 0
A28: Fahrzeitentschädigung | C28: Regiezone | E28: 0 | F28: 0.32 | G28: =PRODUCT(E28:F28) -> 0
A29: Zwischentotal | G29: =SUM(G23:G28) -> 0
A31: Ferienentschädigung | F31: 0.0833 | G31: =PRODUCT(G29*F31) -> 0
A32: AHV pflichtiger Bruttolohn | G32: =SUM(G29+G31) -> 0
A34: AHV/IV/EO | F34: 0.053 | G34: =PRODUCT(G32*F34) -> 0
A35: ALV | F35: 0.011 | G35: =PRODUCT(G32*F35) -> 0
A36: Krankentaggeld/UVG | F36: 0.00821 | G36: =PRODUCT(G32*F36) -> 0
A37: Aus- und Weiterbildungskosten inkl. Ferienentschädigung | E37: =(E23+E24)*1.0833 -> 0 | F37: 0.015 | G37: =PRODUCT(E37,F37) -> 0
A38: Total | G38: =SUM(G32-(G34+G35+G36+G37)) -> 0
A40: Spesen gemäss Nachweis | G40: ='Std-Erf'!C12 -> 0
A42: Total Auszahlung | G42: =ROUND(SUM(G38:G40)*20,0)/20 -> 0
A45: Ferienguthaben | B45: 0 | D45: Krankheitstage bezahlt | F45: 0
A46: Abwesenheit | B46: 0 | D46: Mehrzeit/Unterzeit | F46: 0
A48: Wir bitten Sie die Lohnabrechnung sofort zu prüfen und Unstimmigkeiten schriftlich innerhalb von 10 Tagen
A49: per Mail mitzuteilen!
C51: Freundliche Grüsse
C53: Blesinger Sicherheitsdienste GmbH

Sheet DizH
A1: Blesinger Sicherheits Dienste GmbH
A2: Postfach 28
A3: 6314 Unterägeri
A4: www.blesingersicherheit.ch
A5: info@blesingersicherheit.ch
D7: Herr
D8: Humberto Diz Cortegoso
D9: Albisstrasse 47a
D10: 8932 Mettmenstetten
A12: AHV Nr. 756.6745.9885.44
A14: Lohnblatt | B14: ='Std-Erf'!B1 -> März 2026
A16: Abteilung | B16: Sicherheit | D16: Anstellungskategorie | F16: C
A18: Abrechnungsdatum | B18: ='Std-Erf'!F1 -> 46122 | D18: Anstellungsort | F18: Weinbergstrasse 8, Baar
A19: Gesamtstunden gemäss beigelgtem Stundennachweis | D19: Dienstjahr | F19: 11
A21: Bezeichnung | E21: Einheit | F21: Ansatz | G21: Betrag
A23: Basislohn | D23: Std. | E23: ='Std-Erf'!D13 -> 0 | F23: 30 | G23: =PRODUCT(E23:F23) -> 0
A24: Stunden mit Zeitzuschlag | C24: ='Std-Erf'!E13 -> 0 | D24: Std. | E24: =C24/10 -> 0 | F24: 30 | G24: =PRODUCT(E24:F24) -> 0
A25: Spezialzuschlag gemäss Vertrag | G25: =PRODUCT(E25:F25) -> 0
A26: Fahrzeitentschädigung | C26: Pauschalzone | D26: 1 | E26: 0 | F26: 5.6 | G26: =PRODUCT(E26:F26) -> 0
A27: Fahrzeitentschädigung | C27: Pauschalzone | D27: 2 | E27: 0 | F27: 16.8 | G27: =PRODUCT(E27:F27) -> 0
A28: Fahrzeitentschädigung | C28: Regiezone | E28: 0 | F28: 0.32 | G28: =PRODUCT(E28:F28) -> 0
A29: Zwischentotal | G29: =SUM(G23:G28) -> 0
A31: Ferienentschädigung | F31: 0.0833 | G31: =PRODUCT(G29*F31) -> 0
A32: AHV pflichtiger Bruttolohn | G32: =SUM(G29+G31) -> 0
A34: AHV/IV/EO | F34: 0.053 | G34: =PRODUCT(G32*F34) -> 0
A35: ALV | F35: 0.011 | G35: =PRODUCT(G32*F35) -> 0
A36: Krankentaggeld/UVG | F36: 0.00821 | G36: =PRODUCT(G32*F36) -> 0
A37: Aus- und Weiterbildungskosten inkl. Ferienentschädigung | E37: =(E23+E24)*1.0833 -> 0 | F37: 0.015 | G37: =PRODUCT(E37,F37) -> 0
A38: Total | G38: =SUM(G32-(G34+G35+G36+G37)) -> 0
A40: Spesen gemäss Nachweis | G40: ='Std-Erf'!C13 -> 0
A42: Total Auszahlung | G42: =ROUND(SUM(G38:G40)*20,0)/20 -> 0
A45: Ferienguthaben | B45: 0 | D45: Krankheitstage bezahlt | F45: 0
A46: Abwesenheit | B46: 0 | D46: Mehrzeit/Unterzeit | F46: 0
A48: Wir bitten Sie die Lohnabrechnung sofort zu prüfen und Unstimmigkeiten schriftlich innerhalb von 10 Tagen
A49: per Mail mitzuteilen!
C51: Freundliche Grüsse
C53: Blesinger Sicherheitsdienste GmbH

Sheet DuR
A1: Blesinger Sicherheits Dienste GmbH
A2: Postfach 28
A3: 6314 Unterägeri
A4: www.blesingersicherheit.ch
A5: info@blesingersicherheit.ch
D7: Herr
D8: Renato Duchene
D9: Lorzentobel
D10: 6313 Edlibach
A12: AHV Nr. 756.8264.5410.64
A14: Lohnblatt | B14: ='Std-Erf'!B1 -> März 2026
A16: Abteilung | B16: Sicherheit | D16: Anstellungskategorie | F16: C
A18: Abrechnungsdatum | B18: ='Std-Erf'!F1 -> 46122 | D18: Anstellungsort | F18: Weinbergstrasse 8, Baar
A19: Gesamtstunden gemäss beigelgtem Stundennachweis | D19: Dienstjahr | F19: 18
A21: Bezeichnung | E21: Einheit | F21: Ansatz | G21: Betrag
A23: Basislohn | D23: Std. | E23: ='Std-Erf'!D14 -> 0 | F23: 27.2 | G23: =PRODUCT(E23:F23) -> 0
A24: Stunden mit Zeitzuschlag | C24: ='Std-Erf'!E14 -> 0 | D24: Std. | E24: =C24/10 -> 0 | F24: 27.2 | G24: =PRODUCT(E24:F24) -> 0
A25: Spezialzuschlag gemäss Vertrag | G25: =PRODUCT(E25:F25) -> 0
A26: Fahrzeitentschädigung | C26: Pauschalzone | D26: 1 | E26: 0 | F26: 5.6 | G26: =PRODUCT(E26:F26) -> 0
A27: Fahrzeitentschädigung | C27: Pauschalzone | D27: 2 | E27: 0 | F27: 16.8 | G27: =PRODUCT(E27:F27) -> 0
A28: Fahrzeitentschädigung | C28: Regiezone | E28: 0 | F28: 0.32 | G28: =PRODUCT(E28:F28) -> 0
A29: Zwischentotal | G29: =SUM(G23:G28) -> 0
A31: Ferienentschädigung | F31: 0.1064 | G31: =PRODUCT(G29*F31) -> 0
A32: AHV pflichtiger Bruttolohn | G32: =SUM(G29+G31) -> 0
A34: AHV/IV/EO | F34: 0 | G34: =PRODUCT(G32*F34) -> 0
A35: ALV | F35: 0 | G35: =PRODUCT(G32*F35) -> 0
A36: Krankentaggeld/UVG | F36: 0.00821 | G36: =PRODUCT(G32*F36) -> 0
A37: Aus- und Weiterbildungskosten inkl. Ferienentschädigung | E37: =(E23+E24)*1.0833 -> 0 | F37: 0.015 | G37: =PRODUCT(E37,F37) -> 0
A38: Total | G38: =SUM(G32-(G34+G35+G36+G37)) -> 0
A40: Spesen Schiesskurs Stunden 5 à Fr. 10.00 | G40: 0
A41: Spesen gemäss Nachweis | G41: ='Std-Erf'!C14 -> 0
A43: Total Auszahlung | G43: =ROUND(SUM(G38:G41)*20,0)/20 -> 0
A46: Ferienguthaben | B46: 0 | D46: Krankheitstage bezahlt | F46: 0
A47: Abwesenheit | B47: 0 | D47: Mehrzeit/Unterzeit | F47: 0
A49: Wir bitten Sie die Lohnabrechnung sofort zu prüfen und Unstimmigkeiten schriftlich innerhalb von 10 Tagen
A50: per Mail mitzuteilen!
C52: Freundliche Grüsse
C54: Blesinger Sicherheitsdienste GmbH

Sheet EgliA
A1: Blesinger Sicherheits Dienste GmbH
A2: Postfach 28
A3: 6314 Unterägeri
A4: www.blesingersicherheit.ch
A5: info@blesingersicherheit.ch
D7: Frau
D8: Andrea Egli
D9: Letten 12b
D10: 8484 Weisslingen
A12: AHV Nr. 756.9747.4054.39
A14: Lohnblatt | B14: ='Std-Erf'!B1 -> März 2026
A16: Abteilung | B16: Sicherheit | D16: Anstellungskategorie | F16: C
A18: Abrechnungsdatum | B18: ='Std-Erf'!F1 -> 46122 | D18: Anstellungsort | F18: Weinbergstrasse 8, Baar
A19: Gesamtstunden gemäss beigelgtem Stundennachweis | D19: Dienstjahr | F19: 11
A21: Bezeichnung | E21: Einheit | F21: Ansatz | G21: Betrag
A23: Basislohn | D23: Std. | E23: ='Std-Erf'!D15 -> 0 | F23: 25.2 | G23: =PRODUCT(E23:F23) -> 0
A24: Stunden mit Zeitzuschlag | C24: ='Std-Erf'!E15 -> 0 | D24: Std. | E24: =C24/10 -> 0 | F24: 25.2 | G24: =PRODUCT(E24:F24) -> 0
A25: Spezialzuschlag gemäss Vertrag | E25: =E23 -> 0 | F25: 1.5 | G25: =PRODUCT(E25:F25) -> 0
A26: Fahrzeitentschädigung | C26: Pauschalzone | D26: 1 | E26: 0 | F26: 5.6 | G26: =PRODUCT(E26:F26) -> 0
A27: Fahrzeitentschädigung | C27: Pauschalzone | D27: 2 | E27: 0 | F27: 16.8 | G27: =PRODUCT(E27:F27) -> 0
A28: Fahrzeitentschädigung | C28: Regiezone | E28: 0 | F28: 0.32 | G28: =PRODUCT(E28:F28) -> 0
A29: Zwischentotal | G29: =SUM(G23:G28) -> 0
A31: Ferienentschädigung | F31: 0.1064 | G31: =PRODUCT(G29*F31) -> 0
A32: AHV pflichtiger Bruttolohn | G32: =SUM(G29+G31) -> 0
A34: AHV/IV/EO | F34: 0.053 | G34: =PRODUCT(G32*F34) -> 0
A35: ALV | F35: 0.011 | G35: =PRODUCT(G32*F35) -> 0
A36: Krankentaggeld/UVG | F36: 0.00821 | G36: =PRODUCT(G32*F36) -> 0
A37: Aus- und Weiterbildungskosten inkl. Ferienentschädigung | E37: =(E23+E24)*1.0833 -> 0 | F37: 0.015 | G37: =PRODUCT(E37,F37) -> 0
A38: Total | G38: =SUM(G32-(G34+G35+G36+G37)) -> 0
A41: Spesen gemäss Nachweis | G41: ='Std-Erf'!C15 -> 0
A43: Total Auszahlung | G43: =ROUND(SUM(G38:G41)*20,0)/20 -> 0
A46: Ferienguthaben | B46: 0 | D46: Krankheitstage bezahlt | F46: 0
A47: Abwesenheit | B47: 0 | D47: Mehrzeit/Unterzeit | F47: 0
A49: Wir bitten Sie die Lohnabrechnung sofort zu prüfen und Unstimmigkeiten schriftlich innerhalb von 10 Tagen
A50: per Mail mitzuteilen!
C52: Freundliche Grüsse
C54: Blesinger Sicherheitsdienste GmbH

Sheet EgliB
A1: Blesinger Sicherheits Dienste GmbH
A2: Postfach 28
A3: 6314 Unterägeri
A4: www.blesingersicherheit.ch
A5: info@blesingersicherheit.ch
D7: Frau
D8: Bettina Egli
D9: Soorhaldenstrasse 12
D10: 8308 Illnau
A12: AHV Nr. 756.5497.2740.35
A14: Lohnblatt | B14: ='Std-Erf'!B1 -> März 2026
A16: Abteilung | B16: Sicherheit | D16: Anstellungskategorie | F16: C
A18: Abrechnungsdatum | B18: ='Std-Erf'!F1 -> 46122 | D18: Anstellungsort | F18: Weinbergstrasse 8, Baar
A19: Gesamtstunden gemäss beigelgtem Stundennachweis | D19: Dienstjahr | F19: 1
A21: Bezeichnung | E21: Einheit | F21: Ansatz | G21: Betrag
A23: Basislohn | D23: Std. | E23: ='Std-Erf'!D16 -> 0 | F23: 25.2 | G23: =PRODUCT(E23:F23) -> 0
A24: Stunden mit Zeitzuschlag | C24: ='Std-Erf'!E16 -> 0 | D24: Std. | E24: =C24/10 -> 0 | F24: 25.2 | G24: =PRODUCT(E24:F24) -> 0
A25: Spezialzuschlag gemäss Vertrag | E25: 0 | F25: 0 | G25: =PRODUCT(E25:F25) -> 0
A26: Fahrzeitentschädigung | C26: Pauschalzone | D26: 1 | E26: 0 | F26: 5.6 | G26: =PRODUCT(E26:F26) -> 0
A27: Fahrzeitentschädigung | C27: Pauschalzone | D27: 2 | E27: 0 | F27: 16.8 | G27: =PRODUCT(E27:F27) -> 0
A28: Fahrzeitentschädigung | C28: Regiezone | E28: 0 | F28: 0.32 | G28: =PRODUCT(E28:F28) -> 0
A29: Zwischentotal | G29: =SUM(G23:G28) -> 0
A31: Ferienentschädigung | F31: 0.0833 | G31: =PRODUCT(G29*F31) -> 0
A32: AHV pflichtiger Bruttolohn | G32: =SUM(G29+G31) -> 0
A34: AHV/IV/EO | F34: 0.053 | G34: =PRODUCT(G32*F34) -> 0
A35: ALV | F35: 0.011 | G35: =PRODUCT(G32*F35) -> 0
A36: Krankentaggeld/UVG | F36: 0.00821 | G36: =PRODUCT(G32*F36) -> 0
A37: Aus- und Weiterbildungskosten inkl. Ferienentschädigung | E37: =(E23+E24)*1.0833 -> 0 | F37: 0.015 | G37: =PRODUCT(E37,F37) -> 0
A38: Total | G38: =SUM(G32-(G34+G35+G36+G37)) -> 0
A40: Spesen gemäss Nachweis | G40: ='Std-Erf'!C16 -> 0
A42: Total Auszahlung | G42: =ROUND(SUM(G38:G40)*20,0)/20 -> 0
A45: Ferienguthaben | B45: 0 | D45: Krankheitstage bezahlt | F45: 0
A46: Abwesenheit | B46: 0 | D46: Mehrzeit/Unterzeit | F46: 0
A48: Wir bitten Sie die Lohnabrechnung sofort zu prüfen und Unstimmigkeiten schriftlich innerhalb von 10 Tagen
A49: per Mail mitzuteilen!
C51: Freundliche Grüsse
C53: Blesinger Sicherheitsdienste GmbH

Sheet GabA
A1: Blesinger Sicherheits Dienste GmbH
A2: Postfach 28
A3: 6314 Unterägeri
A4: www.blesingersicherheit.ch
A5: info@blesingersicherheit.ch
D7: Herr
D8: Abraham Gabriel
D9: Schutzengelstrasse 53
D10: 6340 Baar
A12: AHV Nr. 756.4142.0078.68
A14: Lohnblatt | B14: ='Std-Erf'!B1 -> März 2026
A16: Abteilung | B16: Sicherheit | D16: Anstellungskategorie | F16: C
A18: Abrechnungsdatum | B18: ='Std-Erf'!F1 -> 46122 | D18: Anstellungsort | F18: Weinbergstrasse 8, Baar
A19: Gesamtstunden gemäss beigelgtem Stundennachweis | D19: Dienstjahr | F19: 0
A21: Bezeichnung | E21: Einheit | F21: Ansatz | G21: Betrag
A23: Basislohn | D23: Std. | E23: ='Std-Erf'!D17 -> 0 | F23: 27.2 | G23: =PRODUCT(E23:F23) -> 0
A24: Stunden mit Zeitzuschlag | C24: ='Std-Erf'!E17 -> 0 | D24: Std. | E24: =C24/10 -> 0 | F24: 27.2 | G24: =PRODUCT(E24:F24) -> 0
A25: Spezialzuschlag gemäss Vertrag | G25: =PRODUCT(E25:F25) -> 0
A26: Fahrzeitentschädigung | C26: Pauschalzone | D26: 1 | E26: 0 | F26: 5.6 | G26: =PRODUCT(E26:F26) -> 0
A27: Fahrzeitentschädigung | C27: Pauschalzone | D27: 2 | E27: 0 | F27: 16.8 | G27: =PRODUCT(E27:F27) -> 0
A28: Fahrzeitentschädigung | C28: Regiezone | E28: 0 | F28: 0.32 | G28: =PRODUCT(E28:F28) -> 0
A29: Zwischentotal | G29: =SUM(G23:G28) -> 0
A31: Ferienentschädigung | F31: 0.1064 | G31: =PRODUCT(G29*F31) -> 0
A32: AHV pflichtiger Bruttolohn | G32: =SUM(G29+G31) -> 0
A34: AHV/IV/EO | F34: 0.053 | G34: =PRODUCT(G32*F34) -> 0
A35: ALV | F35: 0.011 | G35: =PRODUCT(G32*F35) -> 0
A36: Krankentaggeld/UVG | F36: 0.00821 | G36: =PRODUCT(G32*F36) -> 0
A37: BVG Arbeitnehmeranteil | G37: 410.45
A38: Aus- und Weiterbildungskosten inkl. Ferienentschädigung | E38: =(E23+E24)*1.0833 -> 0 | F38: 0.015 | G38: =PRODUCT(E38,F38) -> 0
A39: Total | G39: =SUM(G32-(G34+G35+G36+G38+G37)) -> -410.45
A41: Spesen gemäss Nachweis | G41: ='Std-Erf'!C17 -> 0
A43: Total Auszahlung | G43: =ROUND(SUM(G39:G41)*20,0)/20 -> -410.45
A46: Ferienguthaben | B46: 0 | D46: Krankheitstage bezahlt | F46: 0
A47: Abwesenheit | B47: 0 | D47: Mehrzeit/Unterzeit | F47: 0
A49: Wir bitten Sie die Lohnabrechnung sofort zu prüfen und Unstimmigkeiten schriftlich innerhalb von 10 Tagen
A50: per Mail mitzuteilen!
C52: Freundliche Grüsse
C54: Blesinger Sicherheitsdienste GmbH

Sheet GabP
A1: Blesinger Sicherheits Dienste GmbH
A2: Postfach 28
A3: 6314 Unterägeri
A4: www.blesingersicherheit.ch
A5: info@blesingersicherheit.ch
D7: Herr
D8: Patrick Gabriel
D9: Schutzengelstrasse 53
D10: 6340 Baar
A12: AHV Nr. 756.6402.2930.73
A14: Lohnblatt | B14: ='Std-Erf'!B1 -> März 2026
A16: Abteilung | B16: Sicherheit | D16: Anstellungskategorie | F16: C
A18: Abrechnungsdatum | B18: ='Std-Erf'!F1 -> 46122 | D18: Anstellungsort | F18: Weinbergstrasse 8, Baar
A19: Gesamtstunden gemäss beigelgtem Stundennachweis | D19: Dienstjahr | F19: 1
A21: Bezeichnung | E21: Einheit | F21: Ansatz | G21: Betrag
A23: Basislohn | D23: Std. | E23: ='Std-Erf'!D18 -> 0 | F23: 25.2 | G23: =PRODUCT(E23:F23) -> 0
A24: Stunden mit Zeitzuschlag | C24: ='Std-Erf'!E18 -> 0 | D24: Std. | E24: =C24/10 -> 0 | F24: 25.2 | G24: =PRODUCT(E24:F24) -> 0
A25: Spezialzuschlag gemäss Vertrag | G25: =PRODUCT(E25:F25) -> 0
A26: Fahrzeitentschädigung | C26: Pauschalzone | D26: 1 | E26: 0 | F26: 5.6 | G26: =PRODUCT(E26:F26) -> 0
A27: Fahrzeitentschädigung | C27: Pauschalzone | D27: 2 | E27: 0 | F27: 16.8 | G27: =PRODUCT(E27:F27) -> 0
A28: Fahrzeitentschädigung | C28: Regiezone | E28: 0 | F28: 0.32 | G28: =PRODUCT(E28:F28) -> 0
A29: Zwischentotal | G29: =SUM(G23:G28) -> 0
A31: Ferienentschädigung | F31: 0.0833 | G31: =PRODUCT(G29*F31) -> 0
A32: AHV pflichtiger Bruttolohn | G32: =SUM(G29+G31) -> 0
A34: AHV/IV/EO | F34: 0.053 | G34: =PRODUCT(G32*F34) -> 0
A35: ALV | F35: 0.011 | G35: =PRODUCT(G32*F35) -> 0
A36: Krankentaggeld/UVG | F36: 0.00821 | G36: =PRODUCT(G32*F36) -> 0
A37: Aus- und Weiterbildungskosten inkl. Ferienentschädigung | E37: =(E23+E24)*1.0833 -> 0 | F37: 0.015 | G37: =PRODUCT(E37,F37) -> 0
A38: Total | G38: =SUM(G32-(G34+G35+G36+G37)) -> 0
A40: Spesen gemäss Nachweis | G40: ='Std-Erf'!C18 -> 0
A42: Total Auszahlung | G42: =ROUND(SUM(G38:G40)*20,0)/20 -> 0
A45: Ferienguthaben | B45: 0 | D45: Krankheitstage bezahlt | F45: 0
A46: Abwesenheit | B46: 0 | D46: Mehrzeit/Unterzeit | F46: 0
A48: Wir bitten Sie die Lohnabrechnung sofort zu prüfen und Unstimmigkeiten schriftlich innerhalb von 10 Tagen
A49: per Mail mitzuteilen!
C51: Freundliche Grüsse
C53: Blesinger Sicherheitsdienste GmbH

Sheet GrBe
A1: Blesinger Sicherheits Dienste GmbH
A2: Postfach 28
A3: 6314 Unterägeri
A4: www.blesingersicherheit.ch
A5: info@blesingersicherheit.ch
D7: Herr
D8: Benedikt Grüter
D9: Günikon 9
D10: 6276 Hohenrain
A12: AHV Nr. 756.4234.8454.22
A14: Lohnblatt | B14: ='Std-Erf'!B1 -> März 2026
A16: Abteilung | B16: Sicherheit | D16: Anstellungskategorie | F16: C
A18: Abrechnungsdatum | B18: ='Std-Erf'!F1 -> 46122 | D18: Anstellungsort | F18: Weinbergstrasse 8, Baar
A19: Gesamtstunden gemäss beigelgtem Stundennachweis | D19: Dienstjahr | F19: 16
A21: Bezeichnung | E21: Einheit | F21: Ansatz | G21: Betrag
A23: Basislohn | D23: Std. | E23: ='Std-Erf'!D19 -> 0 | F23: 25.2 | G23: =PRODUCT(E23:F23) -> 0
A24: Stunden mit Zeitzuschlag | C24: ='Std-Erf'!E19 -> 0 | D24: Std. | E24: =C24/10 -> 0 | F24: 25.2 | G24: =PRODUCT(E24:F24) -> 0
A25: Spezialzuschlag gemäss Vertrag | E25: =E23 -> 0 | F25: 2 | G25: =PRODUCT(E25:F25) -> 0
A26: Fahrzeitentschädigung | C26: Pauschalzone | D26: 1 | E26: 0 | F26: 5.6 | G26: =PRODUCT(E26:F26) -> 0
A27: Fahrzeitentschädigung | C27: Pauschalzone | D27: 2 | E27: 0 | F27: 16.8 | G27: =PRODUCT(E27:F27) -> 0
A28: Fahrzeitentschädigung | C28: Regiezone | E28: 0 | F28: 0.32 | G28: =PRODUCT(E28:F28) -> 0
A29: Zwischentotal | G29: =SUM(G23:G28) -> 0
A31: Ferienentschädigung | F31: 0.0833 | G31: =PRODUCT(G29*F31) -> 0
A32: AHV pflichtiger Bruttolohn | G32: =SUM(G29+G31) -> 0
A34: AHV/IV/EO | F34: 0.053 | G34: =PRODUCT(G32*F34) -> 0
A35: ALV | F35: 0.011 | G35: =PRODUCT(G32*F35) -> 0
A36: Krankentaggeld/UVG | F36: 0.00821 | G36: =PRODUCT(G32*F36) -> 0
A37: Aus- und Weiterbildungskosten inkl. Ferienentschädigung | E37: =(E23+E24)*1.0833 -> 0 | F37: 0.015 | G37: =PRODUCT(E37,F37) -> 0
A38: Total | G38: =SUM(G32-(G34+G35+G36+G37)) -> 0
A40: Spesen gemäss Nachweis | G40: ='Std-Erf'!C19 -> 0
A42: Total Auszahlung | G42: =ROUND(SUM(G38:G40)*20,0)/20 -> 0
A45: Ferienguthaben | B45: 0 | D45: Krankheitstage bezahlt | F45: 0
A46: Abwesenheit | B46: 0 | D46: Mehrzeit/Unterzeit | F46: 0
A48: Wir bitten Sie die Lohnabrechnung sofort zu prüfen und Unstimmigkeiten schriftlich innerhalb von 10 Tagen
A49: per Mail mitzuteilen!
C51: Freundliche Grüsse
C53: Blesinger Sicherheitsdienste GmbH

Sheet HieP
A1: Blesinger Sicherheits Dienste GmbH
A2: Postfach 28
A3: 6314 Unterägeri
A4: www.blesingersicherheit.ch
A5: info@blesingersicherheit.ch
D7: Herr
D8: Philipp Hiestand
D9: Hauptstrasse 1
D10: 6170 Schüpfheim
A12: AHV Nr. 756.8057.3918.90
A14: Lohnblatt | B14: ='Std-Erf'!B1 -> März 2026
A16: Abteilung | B16: Sicherheit | D16: Anstellungskategorie | F16: C
A18: Abrechnungsdatum | B18: ='Std-Erf'!F1 -> 46122 | D18: Anstellungsort | F18: Schachenstr. 7, Emmenbrücke
A19: Gesamtstunden gemäss beigelgtem Stundennachweis | D19: Dienstjahr | F19: 3
A21: Bezeichnung | E21: Einheit | F21: Ansatz | G21: Betrag
A23: Basislohn | D23: Std. | E23: ='Std-Erf'!D20 -> 0 | F23: 25.2 | G23: =PRODUCT(E23:F23) -> 0
A24: Stunden mit Zeitzuschlag | C24: ='Std-Erf'!E20 -> 0 | D24: Std. | E24: =C24/10 -> 0 | F24: 25.2 | G24: =PRODUCT(E24:F24) -> 0
A25: Spezialzuschlag gemäss Vertrag | E25: =E23 -> 0 | F25: 2 | G25: =PRODUCT(E25:F25) -> 0
A26: Fahrzeitentschädigung | C26: Pauschalzone | D26: 1 | E26: 0 | F26: 5.6 | G26: =PRODUCT(E26:F26) -> 0
A27: Fahrzeitentschädigung | C27: Pauschalzone | D27: 2 | E27: 0 | F27: 16.8 | G27: =PRODUCT(E27:F27) -> 0
A28: Fahrzeitentschädigung | C28: Regiezone | E28: 0 | F28: 0.32 | G28: =PRODUCT(E28:F28) -> 0
A29: Zwischentotal | G29: =SUM(G23:G28) -> 0
A31: Ferienentschädigung | F31: 0.0833 | G31: =PRODUCT(G29*F31) -> 0
A32: AHV pflichtiger Bruttolohn | G32: =SUM(G29+G31) -> 0
A34: AHV/IV/EO | F34: 0.053 | G34: =PRODUCT(G32*F34) -> 0
A35: ALV | F35: 0.011 | G35: =PRODUCT(G32*F35) -> 0
A36: Krankentaggeld/UVG | F36: 0.00821 | G36: =PRODUCT(G32*F36) -> 0
A37: Aus- und Weiterbildungskosten inkl. Ferienentschädigung | E37: =(E23+E24)*1.0833 -> 0 | F37: 0.015 | G37: =PRODUCT(E37,F37) -> 0
A38: Total | G38: =SUM(G32-(G34+G35+G36+G37)) -> 0
A40: Spesen gemäss Nachweis | G40: ='Std-Erf'!C20 -> 0
A42: Total Auszahlung | G42: =ROUND(SUM(G38:G40)*20,0)/20 -> 0
A45: Ferienguthaben | B45: 0 | D45: Krankheitstage bezahlt | F45: 0
A46: Abwesenheit | B46: 0 | D46: Mehrzeit/Unterzeit | F46: 0
A48: Wir bitten Sie die Lohnabrechnung sofort zu prüfen und Unstimmigkeiten schriftlich innerhalb von 10 Tagen
A49: per Mail mitzuteilen!
C51: Freundliche Grüsse
C53: Blesinger Sicherheitsdienste GmbH

Sheet HugS
A1: Blesinger Sicherheits Dienste GmbH
A2: Postfach 28
A3: 6314 Unterägeri
A4: www.blesingersicherheit.ch
A5: info@blesingersicherheit.ch
D7: Frau
D8: Shirin Hug
D9: Untere Halten 13
D10: 6032 Emmen
A12: AHV Nr. 756.2155.2643.15
A14: Lohnblatt | B14: ='Std-Erf'!B1 -> März 2026
A16: Abteilung | B16: Sicherheit | D16: Anstellungskategorie | F16: C
A18: Abrechnungsdatum | B18: ='Std-Erf'!F1 -> 46122 | D18: Anstellungsort | F18: Schachenstr. 7, Emmenbrücke
A19: Gesamtstunden gemäss beigelgtem Stundennachweis | D19: Dienstjahr | F19: 3
A21: Bezeichnung | E21: Einheit | F21: Ansatz | G21: Betrag
A23: Basislohn | D23: Std. | E23: ='Std-Erf'!D21 -> 0 | F23: 25.2 | G23: =PRODUCT(E23:F23) -> 0
A24: Stunden mit Zeitzuschlag | C24: ='Std-Erf'!E21 -> 0 | D24: Std. | E24: =C24/10 -> 0 | F24: 25.2 | G24: =PRODUCT(E24:F24) -> 0
A25: Spezialzuschlag gemäss Vertrag | E25: =E23 -> 0 | F25: 2 | G25: =PRODUCT(E25:F25) -> 0
A26: Fahrzeitentschädigung | C26: Pauschalzone | D26: 1 | E26: 0 | F26: 5.6 | G26: =PRODUCT(E26:F26) -> 0
A27: Fahrzeitentschädigung | C27: Pauschalzone | D27: 2 | E27: 0 | F27: 16.8 | G27: =PRODUCT(E27:F27) -> 0
A28: Fahrzeitentschädigung | C28: Regiezone | E28: 0 | F28: 0.32 | G28: =PRODUCT(E28:F28) -> 0
A29: Zwischentotal | G29: =SUM(G23:G28) -> 0
A31: Ferienentschädigung | F31: 0.0833 | G31: =PRODUCT(G29*F31) -> 0
A32: AHV pflichtiger Bruttolohn | G32: =SUM(G29+G31) -> 0
A34: AHV/IV/EO | F34: 0.053 | G34: =PRODUCT(G32*F34) -> 0
A35: ALV | F35: 0.011 | G35: =PRODUCT(G32*F35) -> 0
A36: Krankentaggeld/UVG | F36: 0.00821 | G36: =PRODUCT(G32*F36) -> 0
A37: Aus- und Weiterbildungskosten inkl. Ferienentschädigung | E37: =(E23+E24)*1.0833 -> 0 | F37: 0.015 | G37: =PRODUCT(E37,F37) -> 0
A38: Total | G38: =SUM(G32-(G34+G35+G36+G37)) -> 0
A40: Kinderzulage
A41: Spesen gemäss Nachweis | G41: ='Std-Erf'!C21 -> 0
A43: Total Auszahlung | G43: =ROUND(SUM(G38:G41)*20,0)/20 -> 0
A46: Ferienguthaben | B46: 0 | D46: Krankheitstage bezahlt | F46: 0
A47: Abwesenheit | B47: 0 | D47: Mehrzeit/Unterzeit | F47: 0
A49: Wir bitten Sie die Lohnabrechnung sofort zu prüfen und Unstimmigkeiten schriftlich innerhalb von 10 Tagen
A50: per Mail mitzuteilen!
C52: Freundliche Grüsse
C54: Blesinger Sicherheitsdienste GmbH

Sheet KäJ
A1: Blesinger Sicherheits Dienste GmbH
A2: Postfach 28
A3: 6314 Unterägeri
A4: www.blesingersicherheit.ch
A5: info@blesingersicherheit.ch
D7: Frau
D8: Jannine Käch
D9: Bachmattli 2
D10: 6314 Unterägeri
A12: AHV Nr. 756.1168.7567.49
A14: Lohnblatt | B14: ='Std-Erf'!B1 -> März 2026
A16: Abteilung | B16: Sicherheit | D16: Anstellungskategorie | F16: C
A18: Abrechnungsdatum | B18: ='Std-Erf'!F1 -> 46122 | D18: Anstellungsort | F18: Weinbergstrasse 8, Baar
A19: Gesamtstunden gemäss beigelgtem Stundennachweis | D19: Dienstjahr | F19: 3
A21: Bezeichnung | E21: Einheit | F21: Ansatz | G21: Betrag
A23: Basislohn | D23: Std. | E23: ='Std-Erf'!D22 -> 0 | F23: 27.2 | G23: =PRODUCT(E23:F23) -> 0
A24: Stunden mit Zeitzuschlag | C24: ='Std-Erf'!E22 -> 0 | D24: Std. | E24: =C24/10 -> 0 | F24: 27.2 | G24: =PRODUCT(E24:F24) -> 0
A25: Spezialzuschlag gemäss Vertrag | E25: 0 | F25: 0 | G25: =PRODUCT(E25:F25) -> 0
A26: Fahrzeitentschädigung | C26: Pauschalzone | D26: 1 | E26: 0 | F26: 5.6 | G26: =PRODUCT(E26:F26) -> 0
A27: Fahrzeitentschädigung | C27: Pauschalzone | D27: 2 | E27: 0 | F27: 16.8 | G27: =PRODUCT(E27:F27) -> 0
A28: Fahrzeitentschädigung | C28: Regiezone | E28: 0 | F28: 0.32 | G28: =PRODUCT(E28:F28) -> 0
A29: Zwischentotal | G29: =SUM(G23:G28) -> 0
A31: Ferienentschädigung | F31: 0.0833 | G31: =PRODUCT(G29*F31) -> 0
A32: AHV pflichtiger Bruttolohn | G32: =SUM(G29+G31) -> 0
A34: AHV/IV/EO | F34: 0.053 | G34: =PRODUCT(G32*F34) -> 0
A35: ALV | F35: 0.011 | G35: =PRODUCT(G32*F35) -> 0
A36: Krankentaggeld/UVG | F36: 0.00821 | G36: =PRODUCT(G32*F36) -> 0
A38: Aus- und Weiterbildungskosten inkl. Ferienentschädigung | E38: =(E23+E24)*1.0833 -> 0 | F38: 0.015 | G38: =PRODUCT(E38,F38) -> 0
A39: Total | G39: =SUM(G32-(G34+G35+G36+G37+G38)) -> 0
A41: Spesen gemäss Nachweis | G41: ='Std-Erf'!C22 -> 0
A43: Total Auszahlung | G43: =ROUND(SUM(G39:G41)*20,0)/20 -> 0
A46: Ferienguthaben | B46: 0 | D46: Krankheitstage bezahlt | F46: 0
A47: Abwesenheit | B47: 0 | D47: Mehrzeit/Unterzeit | F47: 0
A49: Wir bitten Sie die Lohnabrechnung sofort zu prüfen und Unstimmigkeiten schriftlich innerhalb von 10 Tagen
A50: per Mail mitzuteilen!
C52: Freundliche Grüsse
C54: Blesinger Sicherheitsdienste GmbH

Sheet KäY
A1: Blesinger Sicherheits Dienste GmbH
A2: Postfach 28
A3: 6314 Unterägeri
A4: www.blesingersicherheit.ch
A5: info@blesingersicherheit.ch
D7: Frau
D8: Yvonne Käch
D9: Unterer Chämletenweg 8
D10: 6333 Hünenberg See
A12: AHV Nr. 756.5327.5578.88
A14: Lohnblatt | B14: ='Std-Erf'!B1 -> März 2026
A16: Abteilung | B16: Administration | D16: Anstellungskategorie | F16: Nicht GAV Pflichtig
A18: Abrechnungsdatum | B18: ='Std-Erf'!F1 -> 46122 | D18: Anstellungsort | F18: Rainstrasse 37, Unterägeri
A19: Gesamtstunden gemäss beigelgtem Stundennachweis | D19: Dienstjahr | F19: 6
A21: Bezeichnung | E21: Einheit | F21: Ansatz | G21: Betrag
A23: Basislohn | D23: Std. | E23: ='Std-Erf'!D23 -> 0 | F23: 33 | G23: =PRODUCT(E23:F23) -> 0
A24: Stunden mit Zeitzuschlag | E24: =C24/10 -> 0 | F24: 0 | G24: =PRODUCT(E24:F24) -> 0
A25: Spezialzuschlag gemäss Vertrag | E25: 0 | F25: 0 | G25: =PRODUCT(E25:F25) -> 0
A26: Fahrzeitentschädigung | C26: Pauschalzone | D26: 1 | E26: 0 | F26: 5.6 | G26: =PRODUCT(E26:F26) -> 0
A27: Fahrzeitentschädigung | C27: Pauschalzone | D27: 2 | E27: 0 | F27: 16.8 | G27: =PRODUCT(E27:F27) -> 0
A28: Fahrzeitentschädigung | C28: Regiezone | E28: 0 | F28: 0.32 | G28: =PRODUCT(E28:F28) -> 0
A29: Zwischentotal | G29: =SUM(G23:G28) -> 0
A31: Ferienentschädigung | F31: 0.1064 | G31: =PRODUCT(G29*F31) -> 0
A32: AHV pflichtiger Bruttolohn | G32: =SUM(G29+G31) -> 0
A34: AHV/IV/EO | F34: 0.053 | G34: =PRODUCT(G32*F34) -> 0
A35: ALV | F35: 0.011 | G35: =PRODUCT(G32*F35) -> 0
A36: Krankentaggeld/UVG | F36: 0.00821 | G36: =PRODUCT(G32*F36) -> 0
A37: BVG Arbeitnehmeranteil
A38: Aus- und Weiterbildungskosten inkl. Ferienentschädigung | G38: =PRODUCT(E38,F38) -> 0
A39: Total | G39: =SUM(G32-(G34+G35+G36+G38+G37)) -> 0
A41: Spesen gemäss Nachweis | G41: ='Std-Erf'!C23 -> 0
A43: Total Auszahlung | G43: =ROUND(SUM(G39:G41)*20,0)/20 -> 0
A46: Ferienguthaben | B46: 0 | D46: Krankheitstage bezahlt | F46: 0
A47: Abwesenheit | B47: 0 | D47: Mehrzeit/Unterzeit | F47: 0
A49: Wir bitten Sie die Lohnabrechnung sofort zu prüfen und Unstimmigkeiten schriftlich innerhalb von 10 Tagen
A50: per Mail mitzuteilen!
C52: Freundliche Grüsse
C54: Blesinger Sicherheitsdienste GmbH

Sheet KolM
A1: Blesinger Sicherheits Dienste GmbH
A2: Postfach 28
A3: 6314 Unterägeri
A4: www.blesingersicherheit.ch
A5: info@blesingersicherheit.ch
D7: Herr
D8: Mike Kolb
D9: Schachenstrasse 7
D10: 6020 Emmenbrücke
A12: AHV Nr. 756.4164.0592.27
A14: Lohnblatt | B14: ='Std-Erf'!B1 -> März 2026
A16: Abteilung | B16: Sicherheit | D16: Anstellungskategorie | F16: C
A18: Abrechnungsdatum | B18: ='Std-Erf'!F1 -> 46122 | D18: Anstellungsort | F18: Schachenstr. 7, Emmenbrücke
A19: Gesamtstunden gemäss beigelgtem Stundennachweis | D19: Dienstjahr | F19: 10
A21: Bezeichnung | E21: Einheit | F21: Ansatz | G21: Betrag
A23: Basislohn | D23: Std. | E23: ='Std-Erf'!D24 -> 0 | F23: 27 | G23: =PRODUCT(E23:F23) -> 0
A24: Stunden mit Zeitzuschlag | C24: ='Std-Erf'!E24 -> 0 | D24: Std. | E24: =C24/10 -> 0 | F24: 27 | G24: =PRODUCT(E24:F24) -> 0
A25: Spezialzuschlag gemäss Vertrag | E25: ='Std-Erf'!D24 -> 0 | F25: 3 | G25: =PRODUCT(E25:F25) -> 0
A26: Fahrzeitentschädigung | C26: Pauschalzone | D26: 1 | E26: 0 | F26: 5.6 | G26: =PRODUCT(E26:F26) -> 0
A27: Fahrzeitentschädigung | C27: Pauschalzone | D27: 2 | E27: 0 | F27: 16.8 | G27: =PRODUCT(E27:F27) -> 0
A28: Fahrzeitentschädigung | C28: Regiezone | E28: 0 | F28: 0.32 | G28: =PRODUCT(E28:F28) -> 0
A29: Zwischentotal | G29: =SUM(G23:G28) -> 0
A31: Ferienentschädigung | F31: 0.1064 | G31: =PRODUCT(G29*F31) -> 0
A32: AHV pflichtiger Bruttolohn | G32: =SUM(G29+G31) -> 0
A34: AHV/IV/EO | F34: 0.053 | G34: =PRODUCT(G32*F34) -> 0
A35: ALV | F35: 0.011 | G35: =PRODUCT(G32*F35) -> 0
A36: Krankentaggeld/UVG | F36: 0.00821 | G36: =PRODUCT(G32*F36) -> 0
A37: Aus- und Weiterbildungskosten inkl. Ferienentschädigung | E37: =(E23+E24)*1.0833 -> 0 | F37: 0.015 | G37: =PRODUCT(E37,F37) -> 0
A38: Total | G38: =SUM(G32-(G34+G35+G36+G37)) -> 0
A40: Spesen gemäss Nachweis | G40: ='Std-Erf'!C24 -> 0
A42: Total Auszahlung | G42: =ROUND(SUM(G38:G41)*20,0)/20 -> 0
A45: Ferienguthaben | B45: 0 | D45: Krankheitstage bezahlt | F45: 0
A46: Abwesenheit | B46: 0 | D46: Mehrzeit/Unterzeit | F46: 0
A48: Wir bitten Sie die Lohnabrechnung sofort zu prüfen und Unstimmigkeiten schriftlich innerhalb von 10 Tagen
A49: per Mail mitzuteilen!
C51: Freundliche Grüsse
C53: Blesinger Sicherheitsdienste GmbH

Sheet KolMSpesen
A1: Blesinger Sicherheits Dienste GmbH
A2: Postfach 28
A3: 6314 Unterägeri
A4: www.blesingersicherheit.ch
A5: info@blesingersicherheit.ch
D7: Herr
D8: Mike Kolb
D9: Schachenstrasse 7
D10: 6020 Emmenbrücke
A12: AHV Nr. 756.4164.0592.27
A14: Lohnblatt | B14: ='Std-Erf'!B1 -> März 2026
A16: Abteilung | B16: Sicherheit | D16: Anstellungskategorie | F16: C
A18: Abrechnungsdatum | B18: ='Std-Erf'!F1 -> 46122 | D18: Anstellungsort | F18: Schachenstr. 7, Emmenbrücke
A19: Gesamtstunden gemäss beigelgtem Stundennachweis | D19: Dienstjahr | F19: 10
A21: Bezeichnung | E21: Einheit | F21: Ansatz | G21: Betrag
A23: Basislohn | D23: Std. | E23: 3.25 | F23: 27 | G23: =PRODUCT(E23:F23) -> 87.75
A24: Stunden mit Zeitzuschlag | C24: ='Std-Erf'!E24 -> 0 | D24: Std. | E24: =C24/10 -> 0 | F24: 27 | G24: =PRODUCT(E24:F24) -> 0
A25: Spezialzuschlag gemäss Vertrag | E25: 3.25 | F25: 3 | G25: =PRODUCT(E25:F25) -> 9.75
A26: Fahrzeitentschädigung | C26: Pauschalzone | D26: 1 | E26: 0 | F26: 5.6 | G26: =PRODUCT(E26:F26) -> 0
A27: Fahrzeitentschädigung | C27: Pauschalzone | D27: 2 | E27: 0 | F27: 16.8 | G27: =PRODUCT(E27:F27) -> 0
A28: Fahrzeitentschädigung | C28: Regiezone | E28: 0 | F28: 0.32 | G28: =PRODUCT(E28:F28) -> 0
A29: Zwischentotal | G29: =SUM(G23:G28) -> 97.5
A31: Ferienentschädigung | F31: 0.1064 | G31: =PRODUCT(G29*F31) -> 10.374
A32: AHV pflichtiger Bruttolohn | G32: =SUM(G29+G31) -> 107.874
A34: AHV/IV/EO | F34: 0.053 | G34: =PRODUCT(G32*F34) -> 5.717322
A35: ALV | F35: 0.011 | G35: =PRODUCT(G32*F35) -> 1.186614
A36: Krankentaggeld/UVG | F36: 0.00821 | G36: =PRODUCT(G32*F36) -> 0.88564554
A37: Aus- und Weiterbildungskosten inkl. Ferienentschädigung | E37: =(E23+E24)*1.0833 -> 3.520725 | F37: 0.015 | G37: =PRODUCT(E37,F37) -> 0.052810875
A38: Total | G38: =SUM(G32-(G34+G35+G36+G37)) -> 100.03161
A40: Spesen gemäss Nachweis | G40: 50
A42: Total Auszahlung | G42: =ROUND(SUM(G38:G41)*20,0)/20 -> 150.05
A45: Ferienguthaben | B45: 0 | D45: Krankheitstage bezahlt | F45: 0
A46: Abwesenheit | B46: 0 | D46: Mehrzeit/Unterzeit | F46: 0
A48: Wir bitten Sie die Lohnabrechnung sofort zu prüfen und Unstimmigkeiten schriftlich innerhalb von 10 Tagen
A49: per Mail mitzuteilen!
C51: Freundliche Grüsse
C53: Blesinger Sicherheitsdienste GmbH

Sheet KosI
A1: Blesinger Sicherheits Dienste GmbH
A2: Postfach 28
A3: 6314 Unterägeri
A4: www.blesingersicherheit.ch
A5: info@blesingersicherheit.ch
D7: Herr
D8: Ivan Kostovic
D9: Luzernerstrasse 8
D10: 6030 Ebikon
A12: AHV Nr. 756.8243.0450.02
A14: Lohnblatt | B14: ='Std-Erf'!B1 -> März 2026
A16: Abteilung | B16: Sicherheit | D16: Anstellungskategorie | F16: C
A18: Abrechnungsdatum | B18: ='Std-Erf'!F1 -> 46122 | D18: Anstellungsort | F18: Schachenstr. 7, Emmenbrücke
A19: Gesamtstunden gemäss beigelgtem Stundennachweis | D19: Dienstjahr | F19: 0
A21: Bezeichnung | E21: Einheit | F21: Ansatz | G21: Betrag
A23: Basislohn | D23: Std. | E23: ='Std-Erf'!D26 -> 0 | F23: 25.2 | G23: =PRODUCT(E23:F23) -> 0
A24: Stunden mit Zeitzuschlag | C24: ='Std-Erf'!E26 -> 0 | D24: Std. | E24: =C24/10 -> 0 | F24: 25.2 | G24: =PRODUCT(E24:F24) -> 0
A25: Spezialzuschlag gemäss Vertrag | G25: =PRODUCT(E25:F25) -> 0
A26: Fahrzeitentschädigung | C26: Pauschalzone | D26: 1 | E26: 0 | F26: 5.6 | G26: =PRODUCT(E26:F26) -> 0
A27: Fahrzeitentschädigung | C27: Pauschalzone | D27: 2 | E27: 0 | F27: 16.8 | G27: =PRODUCT(E27:F27) -> 0
A28: Fahrzeitentschädigung | C28: Regiezone | E28: 0 | F28: 0.32 | G28: =PRODUCT(E28:F28) -> 0
A29: Zwischentotal | G29: =SUM(G23:G28) -> 0
A31: Ferienentschädigung | F31: 0.0833 | G31: =PRODUCT(G29*F31) -> 0
A32: AHV pflichtiger Bruttolohn | G32: =SUM(G29+G31) -> 0
A34: AHV/IV/EO | F34: 0.053 | G34: =PRODUCT(G32*F34) -> 0
A35: ALV | F35: 0.011 | G35: =PRODUCT(G32*F35) -> 0
A36: Krankentaggeld/UVG | F36: 0.00821 | G36: =PRODUCT(G32*F36) -> 0
A37: Aus- und Weiterbildungskosten inkl. Ferienentschädigung | E37: =(E23+E24)*1.0833 -> 0 | F37: 0.015 | G37: =PRODUCT(E37,F37) -> 0
A38: Total | G38: =SUM(G32-(G34+G35+G36+G37)) -> 0
A40: Spesen gemäss Nachweis | G40: ='Std-Erf'!C26 -> 0
A42: Total Auszahlung | G42: =ROUND(SUM(G38:G40)*20,0)/20 -> 0
A45: Ferienguthaben | B45: 0 | D45: Krankheitstage bezahlt | F45: 0
A46: Abwesenheit | B46: 0 | D46: Mehrzeit/Unterzeit | F46: 0
A48: Wir bitten Sie die Lohnabrechnung sofort zu prüfen und Unstimmigkeiten schriftlich innerhalb von 10 Tagen
A49: per Mail mitzuteilen!
C51: Freundliche Grüsse
C53: Blesinger Sicherheitsdienste GmbH

Sheet LinS
A1: Blesinger Sicherheits Dienste GmbH
A2: Postfach 28
A3: 6314 Unterägeri
A4: www.blesingersicherheit.ch
A5: info@blesingersicherheit.ch
D7: Herr
D8: Sebastian Lindenmeyer
D9: Schellenstrasse 25
D10: 8708 Männedorf
A12: AHV Nr. 756.6778.3837.74
A14: Lohnblatt | B14: ='Std-Erf'!B1 -> März 2026
A16: Abteilung | B16: Sicherheit | D16: Anstellungskategorie | F16: C
A18: Abrechnungsdatum | B18: ='Std-Erf'!F1 -> 46122 | D18: Anstellungsort | F18: Weinbergstrasse 8, Baar
A19: Gesamtstunden gemäss beigelgtem Stundennachweis | D19: Dienstjahr | F19: 8
A21: Bezeichnung | E21: Einheit | F21: Ansatz | G21: Betrag
A23: Basislohn | D23: Std. | E23: ='Std-Erf'!D27 -> 0 | F23: 40 | G23: =PRODUCT(E23:F23) -> 0
A24: Stunden mit Zeitzuschlag | C24: ='Std-Erf'!E27 -> 0 | D24: Std. | E24: =C24/10 -> 0 | F24: 40 | G24: =PRODUCT(E24:F24) -> 0
E25: 0 | F25: 0 | G25: =PRODUCT(E25:F25) -> 0
A26: Fahrzeitentschädigung | C26: Pauschalzone | D26: 1 | E26: 0 | F26: 5.6 | G26: =PRODUCT(E26:F26) -> 0
A27: Fahrzeitentschädigung | C27: Pauschalzone | D27: 2 | E27: 0 | F27: 16.8 | G27: =PRODUCT(E27:F27) -> 0
A28: Fahrzeitentschädigung | C28: Regiezone | E28: 0 | F28: 0.32 | G28: =PRODUCT(E28:F28) -> 0
A29: Zwischentotal | G29: =SUM(G23:G28) -> 0
A31: Ferienentschädigung | F31: 0.0833 | G31: =PRODUCT(G29*F31) -> 0
A32: AHV pflichtiger Bruttolohn | G32: =SUM(G29+G31) -> 0
A34: AHV/IV/EO | F34: 0.053 | G34: =PRODUCT(G32*F34) -> 0
A35: ALV | F35: 0.011 | G35: =PRODUCT(G32*F35) -> 0
A36: Krankentaggeld/UVG | F36: 0.00821 | G36: =PRODUCT(G32*F36) -> 0
A37: Aus- und Weiterbildungskosten inkl. Ferienentschädigung | E37: =(E23+E24)*1.0833 -> 0 | F37: 0.015 | G37: =PRODUCT(E37,F37) -> 0
A38: Total | G38: =SUM(G32-(G34+G35+G36+G37)) -> 0
A40: Spesen gemäss Nachweis | G40: ='Std-Erf'!C27 -> 0
A42: Total Auszahlung | G42: =ROUND(SUM(G38:G40)*20,0)/20 -> 0
A45: Ferienguthaben | B45: 0 | D45: Krankheitstage bezahlt | F45: 0
A46: Abwesenheit | B46: 0 | D46: Mehrzeit/Unterzeit | F46: 0
A48: Wir bitten Sie die Lohnabrechnung sofort zu prüfen und Unstimmigkeiten schriftlich innerhalb von 10 Tagen
A49: per Mail mitzuteilen!
C51: Freundliche Grüsse
C53: Blesinger Sicherheitsdienste GmbH

Sheet LusWJ
A1: Blesinger Sicherheits Dienste GmbH
A2: Postfach 28
A3: 6314 Unterägeri
A4: www.blesingersicherheit.ch
A5: info@blesingersicherheit.ch
D7: Herr
D8: Werner Lussi
D9: Löbernstrasse 3
D10: 6330 Cham
A12: AHV Nr. 756.6937.5658.67
A14: Lohnblatt | B14: ='Std-Erf'!B1 -> März 2026
A16: Abteilung | B16: Sicherheit | D16: Anstellungskategorie | F16: C
A18: Abrechnungsdatum | B18: ='Std-Erf'!F1 -> 46122 | D18: Anstellungsort | F18: Weinbergstrasse 8, Baar
A19: Gesamtstunden gemäss beigelgtem Stundennachweis | D19: Dienstjahr | F19: 7
A21: Bezeichnung | E21: Einheit | F21: Ansatz | G21: Betrag
A23: Basislohn | D23: Std. | E23: ='Std-Erf'!D28 -> 0 | F23: 25.2 | G23: =PRODUCT(E23:F23) -> 0
A24: Stunden mit Zeitzuschlag | C24: ='Std-Erf'!E28 -> 0 | D24: Std. | E24: =C24/10 -> 0 | F24: 25.2 | G24: =PRODUCT(E24:F24) -> 0
A25: Spezialzuschlag gemäss Vertrag | G25: =PRODUCT(E25:F25) -> 0
A26: Fahrzeitentschädigung | C26: Pauschalzone | D26: 1 | E26: 0 | F26: 5.6 | G26: =PRODUCT(E26:F26) -> 0
A27: Fahrzeitentschädigung | C27: Pauschalzone | D27: 2 | E27: 0 | F27: 16.8 | G27: =PRODUCT(E27:F27) -> 0
A28: Fahrzeitentschädigung | C28: Regiezone | E28: 0 | F28: 0.32 | G28: =PRODUCT(E28:F28) -> 0
A29: Zwischentotal | G29: =SUM(G23:G28) -> 0
A31: Ferienentschädigung | F31: 0.0833 | G31: =PRODUCT(G29*F31) -> 0
A32: AHV pflichtiger Bruttolohn | G32: =SUM(G29+G31) -> 0
A34: AHV/IV/EO | F34: 0.053 | G34: =PRODUCT(G32*F34) -> 0
A35: ALV | F35: 0.011 | G35: =PRODUCT(G32*F35) -> 0
A36: Krankentaggeld/UVG | F36: 0.00821 | G36: =PRODUCT(G32*F36) -> 0
A37: Aus- und Weiterbildungskosten inkl. Ferienentschädigung | E37: =(E23+E24)*1.0833 -> 0 | F37: 0.015 | G37: =PRODUCT(E37,F37) -> 0
A38: Total | G38: =SUM(G32-(G34+G35+G36+G37)) -> 0
A40: Spesen gemäss Nachweis | G40: ='Std-Erf'!C28 -> 0
A42: Total Auszahlung | G42: =ROUND(SUM(G38:G40)*20,0)/20 -> 0
A45: Ferienguthaben | B45: 0 | D45: Krankheitstage bezahlt | F45: 0
A46: Abwesenheit | B46: 0 | D46: Mehrzeit/Unterzeit | F46: 0
A48: Wir bitten Sie die Lohnabrechnung sofort zu prüfen und Unstimmigkeiten schriftlich innerhalb von 10 Tagen
A49: per Mail mitzuteilen!
C51: Freundliche Grüsse
C53: Blesinger Sicherheitsdienste GmbH

Sheet LusWS
A1: Blesinger Sicherheits Dienste GmbH
A2: Postfach 28
A3: 6314 Unterägeri
A4: www.blesingersicherheit.ch
A5: info@blesingersicherheit.ch
D7: Herr
D8: Werner Lussi Senior
D9: Löbernstrasse 3
